Workbook

Sheet 01_Master_Material
A1: 01_MASTER_MATERIAL | Warehouse Operations in a Heavy Equipment Manufacturing Environment
A3: Material Code | B3: Material Description | C3: Material Group | D3: Base UoM | E3: Primary Supplier Code | F3: Default Storage Location | G3: Standard Cost (per Base UoM) | H3: Criticality Flag | I3: Storage/Handling Class | J3: Min Stock Level | K3: Max Stock Level | L3: Lead Time (Days) | M3: Status | N3: Remarks
A4: MAT-00001 | B4: Hydraulic Cylinder Seal Kit 80mm | C4: Hydraulic Components | D4: PCS | E4: SUP-0012 | F4: A-01-01-01 | G4: 750000 | H4: Critical Spare | I4: Standard | J4: 20 | K4: 100 | L4: 14 | M4: Active
A5: MAT-00002 | B5: Steel Plate 10mm x 2m x 1m | C5: Raw Materials | D5: PCS | E5: SUP-0005 | F5: C-01-01-01 | G5: 4200000 | H5: Standard | I5: Heavy/Bulk | J5: 10 | K5: 50 | L5: 21 | M5: Active
A6: MAT-00003 | B6: Engine Oil Filter (Cat 320D) | C6: Filters | D6: PCS | E6: SUP-0021 | F6: A-02-01-01 | G6: 250000 | H6: Critical Spare | I6: Standard | J6: 50 | K6: 300 | L6: 7 | M6: Active
A7: MAT-00004 | B7: Hex Bolt M12x50 Grade 8.8 | C7: Fasteners | D7: PCS | E7: SUP-0009 | F7: D-01-01-01 | G7: 8000 | H7: Standard | I7: Standard | J7: 500 | K7: 5000 | L7: 10 | M7: Active
A8: MAT-00005 | B8: Industrial Degreaser 20L | C8: Consumables | D8: LTR | E8: SUP-0014 | F8: D-02-01-01 | G8: 950000 | H8: Standard | I8: Hazardous | J8: 40 | K8: 200 | L8: 5 | M8: Active
A9: MAT-00006 | B9: Track Roller Assembly | C9: Undercarriage Components | D9: PCS | E9: SUP-0012 | F9: B-01-01-01 | G9: 6800000 | H9: Critical Spare | I9: Heavy/Bulk | J9: 4 | K9: 20 | L9: 30 | M9: Active
A10: MAT-00007 | B10: Air Filter Element - Primary | C10: Filters | D10: PCS | E10: SUP-0021 | F10: A-02-01-02 | G10: 420000 | H10: Standard | I10: Standard | J10: 30 | K10: 150 | L10: 10 | M10: Active
A11: MAT-00008 | B11: Hydraulic Hose 1/2in x 3m | C11: Hydraulic Components | D11: PCS | E11: SUP-0012 | F11: A-01-02-01 | G11: 680000 | H11: Critical Spare | I11: Standard | J11: 15 | K11: 80 | L11: 12 | M11: Active
A12: MAT-00009 | B12: Grease Cartridge NLGI2 400g | C12: Lubricants & Fluids | D12: PCS | E12: SUP-0014 | F12: D-02-02-01 | G12: 95000 | H12: Standard | I12: Standard | J12: 60 | K12: 400 | L12: 5 | M12: Active
A13: MAT-00010 | B13: Welding Electrode E7018 3.2mm | C13: Consumables | D13: KG | E13: SUP-0005 | F13: D-02-01-02 | G13: 380000 | H13: Standard | I13: Standard | J13: 100 | K13: 600 | L13: 7 | M13: Active
A14: MAT-00011 | B14: Final Drive Motor (Excavator PC200) | C14: Undercarriage Components | D14: PCS | E14: SUP-0033 | F14: B-01-02-01 | G14: 28500000 | H14: Critical Spare | I14: Heavy/Bulk | J14: 2 | K14: 10 | L14: 45 | M14: Active
A15: MAT-00012 | B15: Bucket Teeth (CAT style) | C15: Undercarriage Components | D15: PCS | E15: SUP-0033 | F15: B-02-01-01 | G15: 620000 | H15: Critical Spare | I15: Standard | J15: 25 | K15: 120 | L15: 20 | M15: Active
... A23: MAT-00020 | B23: Undercarriage Chain Link Assembly | C23: Undercarriage Components | D23: PCS | E23: SUP-0033 | F23: B-02-02-01 | G23: 8900000 | H23: Critical Spare | I23: Heavy/Bulk | J23: 2 | K23: 8 | L23: 40 | M23: Inactive
A26: Notes / Data Dictionary
A27: - Material Code: Primary key. Format MAT-##### used consistently across all worksheets.
A28: - ABC Classification: A = high value/usage, B = moderate, C = low value/high volume.
A29: - Criticality Flag: 'Critical Spare' = stockout risk causes production/machine downtime.
A30: - Conversion Factor: Multiply Purchase UoM quantity by this factor to obtain Base UoM quantity (used in PO/GR reconciliation).
A31: - Status: Only 'Active' materials should be used in new transactions.
A33: No | B33: Column | C33: Mengapa ada? | E33: Material Code | F33: Material Description | G33: Base UoM | H33: Standard Cost (IDR per Base UoM)
A34: 1 | B34: Material Code | C34: Primary key seluruh workbook | E34: MAT-0001 | F34: Hydraulic Cylinder Seal Kit 80mm | G34: PCS | H34: 750000
A35: 2 | B35: Material Description | C35: Nama material | E35: MAT-0002 | F35: Steel Plate 10mm x 2m x 1m | G35: PCS | H35: 4200000
A36: 3 | B36: Material Group | C36: Kategori dashboard | E36: MAT-0003 | F36: Engine Oil Filter | G36: PCS | H36: 250000
A37: 4 | B37: Base UoM | C37: Satuan stok | E37: MAT-0004 | F37: Hex Bolt M12x50 Grade 8.8 | G37: PCS | H37: 8000
A38: 5 | B38: Primary Supplier Code | C38: Default supplier untuk PO | E38: MAT-0005 | F38: Industrial Degreaser 20L | G38: PAIL | H38: 950000
A39: 6 | B39: Default Storage Location | C39: Referensi Put Away | E39: MAT-0006 | F39: Track Roller Assembly | G39: PCS | H39: 6800000
A40: 7 | B40: Standard Cost | C40: Inventory valuation | E40: MAT-0007 | F40: Air Filter Element - Primary | G40: PCS | H40: 420000
A41: 8 | B41: Criticality Flag | C41: Prioritas spare part | E41: MAT-0008 | F41: Hydraulic Hose 1/2in x 3m | G41: PCS | H41: 680000
A42: 9 | B42: Storage/Handling Class | C42: Aturan penyimpanan | E42: MAT-0009 | F42: Grease Cartridge NLGI2 400g | G42: PCS | H42: 95000
A43: 10 | B43: Min Stock Level | C43: Low stock alert | E43: MAT-0010 | F43: Welding Electrode E7018 3.2mm | G43: BOX | H43: 380000
A44: 11 | B44: Max Stock Level | C44: Maximum inventory | E44: MAT-0011 | F44: Final Drive Motor | G44: PCS | H44: 28500000
A45: 12 | B45: Lead Time (Days) | C45: Planning pembelian | E45: MAT-0012 | F45: Bucket Tooth | G45: PCS | H45: 620000
... A47: 14 | B47: Remarks | C47: Catatan | E47: MAT-0014 | F47: Flat Washer M12 Zinc Plated | G47: PCS | H47: 2000
E48: MAT-0015 | F48: Turbocharger Assembly | G48: PCS | H48: 15500000
E49: MAT-0016 | F49: V-Belt A-Section 1250mm | G49: PCS | H49: 185000
E50: MAT-0017 | F50: Steel Beam 6m Length | G50: PCS | H50: 5600000
E51: MAT-0018 | F51: Cabin Air Filter | G51: PCS | H51: 320000
E52: MAT-0019 | F52: Bearing 6205-2RS | G52: PCS | H52: 75000
...

Sheet 02_Master_Supplier
A1: 02_MASTER_SUPPLIER | Warehouse Operations in a Heavy Equipment Manufacturing Environment
A3: Supplier Code | B3: Supplier Name | C3: Supplier Type | D3: Supplier Category | E3: Country | F3: Contact Person | G3: Contact Email | H3: Contact Phone | I3: Supplier Rating | J3: Status
A4: SUP-0005 | B4: PT Krakatau Steel Distribusi | C4: Authorized Distributor | D4: Local | E4: Indonesia | F4: Budi Santoso | G4: budi.santoso@krakatau-dist.co.id | H4: 021-5501234 | I4: Preferred | J4: Active
A5: SUP-0009 | B5: PT Fastener Nusantara | C5: Local Trader | D5: Local | E5: Indonesia | F5: Rina Wulandari | G5: rina@fastenernusantara.co.id | H5: 021-5502345 | I5: Approved | J5: Active
A6: SUP-0012 | B6: Komatsu Parts Indonesia | C6: Authorized Distributor | D6: Local | E6: Indonesia | F6: Agus Prasetyo | G6: agus.p@komatsuparts.co.id | H6: 021-5503456 | I6: Preferred | J6: Active
A7: SUP-0014 | B7: PT Kimia Pelumas Industri | C7: Local Trader | D7: Local | E7: Indonesia | F7: Siti Rahayu | G7: siti.rahayu@kpi-lube.co.id | H7: 021-5504567 | I7: Approved | J7: Active
A8: SUP-0021 | B8: Caterpillar Engine Parts Distributor | C8: Authorized Distributor | D8: Import | E8: Singapore | F8: Michael Tan | G8: michael.tan@catengine-sg.com | H8: +65-6511-2233 | I8: Preferred | J8: Active
A9: SUP-0033 | B9: Original Equipment Spares Corp | C9: Manufacturer | D9: Import | E9: Japan | F9: Kenji Watanabe | G9: k.watanabe@oescorp.jp | H9: +81-3-4455-6677 | I9: Preferred | J9: Active
A10: SUP-0002 | B10: PT Sumber Baja Perkasa | C10: Local Trader | D10: Local | E10: Indonesia | F10: Dedi Kurniawan | G10: dedi@sumberbaja.co.id | H10: 022-6601122 | I10: Under Review | J10: Active
A11: SUP-0018 | B11: Global Hydraulic Supply Pte Ltd | C11: Authorized Distributor | D11: Import | E11: Singapore | F11: Lisa Ong | G11: lisa.ong@ghsupply.sg | H11: +65-6522-3344 | I11: Approved | J11: Active
A12: SUP-0025 | B12: PT Mitra Konsumabel Industri | C12: Local Trader | D12: Local | E12: Indonesia | F12: Andi Firmansyah | G12: andi@mitrakonsumabel.co.id | H12: 021-5507890 | I12: Approved | J12: Active
A13: SUP-0040 | B13: Heavy Equipment Parts Trading Co. | C13: Local Trader | D13: Local | E13: Indonesia | F13: Yusuf Hidayat | G13: yusuf@heptrading.co.id | H13: 021-5508901 | I13: Under Review | J13: Inactive
A16: Notes / Data Dictionary
A17: - Supplier Code: Primary key. Must match Primary Supplier Code values used in 01_Master_Material.
A18: - Supplier Type: Manufacturer = direct OEM source; Authorized Distributor = official regional channel; Local Trader = non-exclusive reseller.
A19: - Supplier Rating: Purchasing-assigned reliability tier. 'Under Review' should not be used for new Critical Spare orders.
A20: - Assumption: Payment Terms, Tax ID, and Currency are out of scope (no Finance/AP worksheet exists).
A21: - Status: Only 'Active' suppliers should be selectable when creating a new Purchase Order.

Sheet 03_Master_Location
A1: 03_MASTER_LOCATION | Warehouse Operations in a Heavy Equipment Manufacturing Environment
A3: Location Code | B3: Location Description | C3: Zone | D3: Storage/Handling Requirement | E3: Pickable Flag | F3: Capacity (Max Qty) | G3: Status
A4: RCV-DOCK-01 | B4: Receiving Dock 1 | C4: Receiving | D4: Standard | E4: No | F4: 50 | G4: Active
A5: RCV-DOCK-02 | B5: Receiving Dock 2 (Heavy Cargo) | C5: Receiving | D5: Heavy/Bulk | E5: No | F5: 20 | G5: Active
A6: BLK-A-01 | B6: Bulk Storage Rack A-01 (Steel Plates) | C6: Storage | D6: Heavy/Bulk | E6: Yes | F6: 40 | G6: Active
A7: BLK-A-02 | B7: Bulk Storage Rack A-02 | C7: Storage | D7: Heavy/Bulk | E7: Yes | F7: 40 | G7: Active
A8: RCK-B-01-01 | B8: Standard Racking B-01 Level 1 | C8: Storage | D8: Standard | E8: Yes | F8: 200 | G8: Active
A9: RCK-B-01-02 | B9: Standard Racking B-01 Level 2 | C9: Storage | D9: Standard | E9: Yes | F9: 200 | G9: Active
A10: RCK-B-02-01 | B10: Standard Racking B-02 Level 1 | C10: Storage | D10: Standard | E10: Yes | F10: 200 | G10: Active
A11: HAZ-C-01 | B11: Hazardous Storage Cabinet C-01 | C11: Storage | D11: Hazardous | E11: Yes | F11: 60 | G11: Active
A12: QC-HOLD-01 | B12: Quarantine / QC Hold Area 1 | C12: Quarantine/QC Hold | D12: Standard | E12: No | F12: 30 | G12: Active
A13: SHP-STG-01 | B13: Shipping Staging Area 1 | C13: Shipping/Staging | D13: Standard | E13: No | F13: 50 | G13: Active
A14: RCK-B-03-01 | B14: Standard Racking B-03 Level 1 (Under Maintenance) | C14: Storage | D14: Standard | E14: No | F14: 200 | G14: Inactive
A17: Notes / Data Dictionary
A18: - Location Code: Primary key, format ZONE-RACK-LEVEL. Foreign key used in Put-Away, Stock Card, and Cycle Count.
A19: - Zone: Functional workflow stage. Only 'Storage' zone locations are expected to be Pickable = Yes.
A20: - Storage/Handling Requirement: Uses the same value list as Storage/Handling Class in 01_Master_Material.
A21: - Pickable Flag: Business rule enforced in 08_Picking_List.
A22: - Capacity (Max Qty): Denominator for the Dashboard's warehouse utilization KPI.
A23: - Design note: Current Utilization (%) is intentionally NOT stored here; it is calculated in 12_Dashboard from Stock Card data.

Sheet 04_Purchase_Order
A1: 04_PURCHASE_ORDER | Warehouse Operations in a Heavy Equipment Manufacturing Environment
A3: PO Number | B3: PO Line | C3: PO Date | D3: Supplier Code | E3: Supplier Name | F3: Material Code | G3: Material Description | H3: Purchase UoM | I3: Order Quantity | J3: Unit Price | K3: Line Total | L3: Conversion Factor (Ref) | M3: Standard Cost Equivalent | N3: Price Variance | O3: Price Variance % | P3: Order Priority | Q3: Lead Time (Days) Ref | R3: Expected Delivery Date | S3: Cancelled Flag | T3: PO Status | U3: Remarks | V3: PO Line Key (Helper)
A4: PO-2026-0001 | B4: 10 | C4: 46174 | D4: SUP-0012 | E4: =INDEX('02_Master_Supplier'!$B:$B,MATCH(D4,'02_Master_Supplier'!$A:$A,0)) -> Komatsu Parts Indonesia | F4: MAT-00001 | G4: =INDEX('01_Master_Material'!$B:$B,MATCH(F4,'01_Master_Material'!$A:$A,0)) -> Hydraulic Cylinder Seal Kit 80mm | H4: =INDEX('01_Master_Material'!#REF!,MATCH(F4,'01_Master_Material'!$A:$A,0)) -> #REF! | I4: 5 | J4: 1500 | K4: =I4*J4 -> 7500 | L4: =INDEX('01_Master_Material'!#REF!,MATCH(F4,'01_Master_Material'!$A:$A,0)) -> #REF! | M4: =INDEX('01_Master_Material'!$G:$G,MATCH(F4,'01_Master_Material'!$A:$A,0))*L4 -> #REF! | N4: =J4-M4 -> #REF! | O4: =IFERROR(N4/M4,0) -> 0 | P4: Standard | Q4: =INDEX('01_Master_Material'!$L:$L,MATCH(F4,'01_Master_Material'!$A:$A,0)) -> 14 | R4: =C4+Q4 -> 46188 | S4: No | T4: =IF($S4="Yes","Cancelled",IF(SUMIFS('05_Goods_Receipt'!$N:$N,'05_Goods_Receipt'!$D:$D,$A4,'05_Goods_Receipt'!$E:$E,$B4)>=I4,"Closed",IF(SUMIFS('05_Goods_Receipt'!$N:$N,'05_Goods_Receipt'!$D:$D,$A4,'05_Goods_Receipt'!$E:$E,$B4)>0,"Partially Received","Open"))) -> Closed | V4: =A4&"-"&B4 -> PO-2026-0001-10
A5: PO-2026-0001 | B5: 20 | C5: 46174 | D5: SUP-0012 | E5: =INDEX('02_Master_Supplier'!$B:$B,MATCH(D5,'02_Master_Supplier'!$A:$A,0)) -> Komatsu Parts Indonesia | F5: MAT-00008 | G5: =INDEX('01_Master_Material'!$B:$B,MATCH(F5,'01_Master_Material'!$A:$A,0)) -> Hydraulic Hose 1/2in x 3m | H5: =INDEX('01_Master_Material'!#REF!,MATCH(F5,'01_Master_Material'!$A:$A,0)) -> #REF! | I5: 30 | J5: 52 | K5: =I5*J5 -> 1560 | L5: =INDEX('01_Master_Material'!#REF!,MATCH(F5,'01_Master_Material'!$A:$A,0)) -> #REF! | M5: =INDEX('01_Master_Material'!$G:$G,MATCH(F5,'01_Master_Material'!$A:$A,0))*L5 -> #REF! | N5: =J5-M5 -> #REF! | O5: =IFERROR(N5/M5,0) -> 0 | P5: Standard | Q5: =INDEX('01_Master_Material'!$L:$L,MATCH(F5,'01_Master_Material'!$A:$A,0)) -> 12 | R5: =C5+Q5 -> 46186 | S5: No | T5: =IF($S5="Yes","Cancelled",IF(SUMIFS('05_Goods_Receipt'!$N:$N,'05_Goods_Receipt'!$D:$D,$A5,'05_Goods_Receipt'!$E:$E,$B5)>=I5,"Closed",IF(SUMIFS('05_Goods_Receipt'!$N:$N,'05_Goods_Receipt'!$D:$D,$A5,'05_Goods_Receipt'!$E:$E,$B5)>0,"Partially Received","Open"))) -> Partially Received | V5: =A5&"-"&B5 -> PO-2026-0001-20
A6: PO-2026-0002 | B6: 10 | C6: 46178 | D6: SUP-0021 | E6: =INDEX('02_Master_Supplier'!$B:$B,MATCH(D6,'02_Master_Supplier'!$A:$A,0)) -> Caterpillar Engine Parts Distributor | F6: MAT-00015 | G6: =INDEX('01_Master_Material'!$B:$B,MATCH(F6,'01_Master_Material'!$A:$A,0)) -> Turbocharger Assembly (Cat C15) | H6: =INDEX('01_Master_Material'!#REF!,MATCH(F6,'01_Master_Material'!$A:$A,0)) -> #REF! | I6: 2 | J6: 1450 | K6: =I6*J6 -> 2900 | L6: =INDEX('01_Master_Material'!#REF!,MATCH(F6,'01_Master_Material'!$A:$A,0)) -> #REF! | M6: =INDEX('01_Master_Material'!$G:$G,MATCH(F6,'01_Master_Material'!$A:$A,0))*L6 -> #REF! | N6: =J6-M6 -> #REF! | O6: =IFERROR(N6/M6,0) -> 0 | P6: Urgent | Q6: =INDEX('01_Master_Material'!$L:$L,MATCH(F6,'01_Master_Material'!$A:$A,0)) -> 35 | R6: =C6+Q6 -> 46213 | S6: No | T6: =IF($S6="Yes","Cancelled",IF(SUMIFS('05_Goods_Receipt'!$N:$N,'05_Goods_Receipt'!$D:$D,$A6,'05_Goods_Receipt'!$E:$E,$B6)>=I6,"Closed",IF(SUMIFS('05_Goods_Receipt'!$N:$N,'05_Goods_Receipt'!$D:$D,$A6,'05_Goods_Receipt'!$E:$E,$B6)>0,"Partially Received","Open"))) -> Open | U6: Emergency replacement - unit down | V6: =A6&"-"&B6 -> PO-2026-0002-10
A7: PO-2026-0002 | B7: 20 | C7: 46178 | D7: SUP-0021 | E7: =INDEX('02_Master_Supplier'!$B:$B,MATCH(D7,'02_Master_Supplier'!$A:$A,0)) -> Caterpillar Engine Parts Distributor | F7: MAT-00003 | G7: =INDEX('01_Master_Material'!$B:$B,MATCH(F7,'01_Master_Material'!$A:$A,0)) -> Engine Oil Filter (Cat 320D) | H7: =INDEX('01_Master_Material'!#REF!,MATCH(F7,'01_Master_Material'!$A:$A,0)) -> #REF! | I7: 10 | J7: 430 | K7: =I7*J7 -> 4300 | L7: =INDEX('01_Master_Material'!#REF!,MATCH(F7,'01_Master_Material'!$A:$A,0)) -> #REF! | M7: =INDEX('01_Master_Material'!$G:$G,MATCH(F7,'01_Master_Material'!$A:$A,0))*L7 -> #REF! | N7: =J7-M7 -> #REF! | O7: =IFERROR(N7/M7,0) -> 0 | P7: Standard | Q7: =INDEX('01_Master_Material'!$L:$L,MATCH(F7,'01_Master_Material'!$A:$A,0)) -> 7 | R7: =C7+Q7 -> 46185 | S7: No | T7: =IF($S7="Yes","Cancelled",IF(SUMIFS('05_Goods_Receipt'!$N:$N,'05_Goods_Receipt'!$D:$D,$A7,'05_Goods_Receipt'!$E:$E,$B7)>=I7,"Closed",IF(SUMIFS('05_Goods_Receipt'!$N:$N,'05_Goods_Receipt'!$D:$D,$A7,'05_Goods_Receipt'!$E:$E,$B7)>0,"Partially Received","Open"))) -> Partially Received | V7: =A7&"-"&B7 -> PO-2026-0002-20
A8: PO-2026-0003 | B8: 10 | C8: 46183 | D8: SUP-0005 | E8: =INDEX('02_Master_Supplier'!$B:$B,MATCH(D8,'02_Master_Supplier'!$A:$A,0)) -> PT Krakatau Steel Distribusi | F8: MAT-00002 | G8: =INDEX('01_Master_Material'!$B:$B,MATCH(F8,'01_Master_Material'!$A:$A,0)) -> Steel Plate 10mm x 2m x 1m | H8: =INDEX('01_Master_Material'!#REF!,MATCH(F8,'01_Master_Material'!$A:$A,0)) -> #REF! | I8: 15 | J8: 315 | K8: =I8*J8 -> 4725 | L8: =INDEX('01_Master_Material'!#REF!,MATCH(F8,'01_Master_Material'!$A:$A,0)) -> #REF! | M8: =INDEX('01_Master_Material'!$G:$G,MATCH(F8,'01_Master_Material'!$A:$A,0))*L8 -> #REF! | N8: =J8-M8 -> #REF! | O8: =IFERROR(N8/M8,0) -> 0 | P8: Standard | Q8: =INDEX('01_Master_Material'!$L:$L,MATCH(F8,'01_Master_Material'!$A:$A,0)) -> 21 | R8: =C8+Q8 -> 46204 | S8: No | T8: =IF($S8="Yes","Cancelled",IF(SUMIFS('05_Goods_Receipt'!$N:$N,'05_Goods_Receipt'!$D:$D,$A8,'05_Goods_Receipt'!$E:$E,$B8)>=I8,"Closed",IF(SUMIFS('05_Goods_Receipt'!$N:$N,'05_Goods_Receipt'!$D:$D,$A8,'05_Goods_Receipt'!$E:$E,$B8)>0,"Partially Received","Open"))) -> Open | V8: =A8&"-"&B8 -> PO-2026-0003-10
A9: PO-2026-0003 | B9: 20 | C9: 46183 | D9: SUP-0005 | E9: =INDEX('02_Master_Supplier'!$B:$B,MATCH(D9,'02_Master_Supplier'!$A:$A,0)) -> PT Krakatau Steel Distribusi | F9: MAT-00017 | G9: =INDEX('01_Master_Material'!$B:$B,MATCH(F9,'01_Master_Material'!$A:$A,0)) -> Steel I-Beam 6m Length | H9: =INDEX('01_Master_Material'!#REF!,MATCH(F9,'01_Master_Material'!$A:$A,0)) -> #REF! | I9: 8 | J9: 625 | K9: =I9*J9 -> 5000 | L9: =INDEX('01_Master_Material'!#REF!,MATCH(F9,'01_Master_Material'!$A:$A,0)) -> #REF! | M9: =INDEX('01_Master_Material'!$G:$G,MATCH(F9,'01_Master_Material'!$A:$A,0))*L9 -> #REF! | N9: =J9-M9 -> #REF! | O9: =IFERROR(N9/M9,0) -> 0 | P9: Standard | Q9: =INDEX('01_Master_Material'!$L:$L,MATCH(F9,'01_Master_Material'!$A:$A,0)) -> 25 | R9: =C9+Q9 -> 46208 | S9: Yes | T9: =IF($S9="Yes","Cancelled",IF(SUMIFS('05_Goods_Receipt'!$N:$N,'05_Goods_Receipt'!$D:$D,$A9,'05_Goods_Receipt'!$E:$E,$B9)>=I9,"Closed",IF(SUMIFS('05_Goods_Receipt'!$N:$N,'05_Goods_Receipt'!$D:$D,$A9,'05_Goods_Receipt'!$E:$E,$B9)>0,"Partially Received","Open"))) -> Cancelled | U9: Project scope changed | V9: =A9&"-"&B9 -> PO-2026-0003-20
A10: PO-2026-0004 | B10: 10 | C10: 46185 | D10: SUP-0033 | E10: =INDEX('02_Master_Supplier'!$B:$B,MATCH(D10,'02_Master_Supplier'!$A:$A,0)) -> Original Equipment Spares Corp | F10: MAT-00011 | G10: =INDEX('01_Master_Material'!$B:$B,MATCH(F10,'01_Master_Material'!$A:$A,0)) -> Final Drive Motor (Excavator PC200) | H10: =INDEX('01_Master_Material'!#REF!,MATCH(F10,'01_Master_Material'!$A:$A,0)) -> #REF! | I10: 1 | J10: 2500 | K10: =I10*J10 -> 2500 | L10: =INDEX('01_Master_Material'!#REF!,MATCH(F10,'01_Master_Material'!$A:$A,0)) -> #REF! | M10: =INDEX('01_Master_Material'!$G:$G,MATCH(F10,'01_Master_Material'!$A:$A,0))*L10 -> #REF! | N10: =J10-M10 -> #REF! | O10: =IFERROR(N10/M10,0) -> 0 | P10: Urgent | Q10: =INDEX('01_Master_Material'!$L:$L,MATCH(F10,'01_Master_Material'!$A:$A,0)) -> 45 | R10: =C10+Q10 -> 46230 | S10: No | T10: =IF($S10="Yes","Cancelled",IF(SUMIFS('05_Goods_Receipt'!$N:$N,'05_Goods_Receipt'!$D:$D,$A10,'05_Goods_Receipt'!$E:$E,$B10)>=I10,"Closed",IF(SUMIFS('05_Goods_Receipt'!$N:$N,'05_Goods_Receipt'!$D:$D,$A10,'05_Goods_Receipt'!$E:$E,$B10)>0,"Partially Received","Open"))) -> Open | U10: Critical spare - low stock | V10: =A10&"-"&B10 -> PO-2026-0004-10
A11: PO-2026-0004 | B11: 20 | C11: 46185 | D11: SUP-0033 | E11: =INDEX('02_Master_Supplier'!$B:$B,MATCH(D11,'02_Master_Supplier'!$A:$A,0)) -> Original Equipment Spares Corp | F11: MAT-00020 | G11: =INDEX('01_Master_Material'!$B:$B,MATCH(F11,'01_Master_Material'!$A:$A,0)) -> Undercarriage Chain Link Assembly | H11: =INDEX('01_Master_Material'!#REF!,MATCH(F11,'01_Master_Material'!$A:$A,0)) -> #REF! | I11: 2 | J11: 1100 | K11: =I11*J11 -> 2200 | L11: =INDEX('01_Master_Material'!#REF!,MATCH(F11,'01_Master_Material'!$A:$A,0)) -> #REF! | M11: =INDEX('01_Master_Material'!$G:$G,MATCH(F11,'01_Master_Material'!$A:$A,0))*L11 -> #REF! | N11: =J11-M11 -> #REF! | O11: =IFERROR(N11/M11,0) -> 0 | P11: Standard | Q11: =INDEX('01_Master_Material'!$L:$L,MATCH(F11,'01_Master_Material'!$A:$A,0)) -> 40 | R11: =C11+Q11 -> 46225 | S11: No | T11: =IF($S11="Yes","Cancelled",IF(SUMIFS('05_Goods_Receipt'!$N:$N,'05_Goods_Receipt'!$D:$D,$A11,'05_Goods_Receipt'!$E:$E,$B11)>=I11,"Closed",IF(SUMIFS('05_Goods_Receipt'!$N:$N,'05_Goods_Receipt'!$D:$D,$A11,'05_Goods_Receipt'!$E:$E,$B11)>0,"Partially Received","Open"))) -> Open | V11: =A11&"-"&B11 -> PO-2026-0004-20
A12: PO-2026-0005 | B12: 10 | C12: 46188 | D12: SUP-0009 | E12: =INDEX('02_Master_Supplier'!$B:$B,MATCH(D12,'02_Master_Supplier'!$A:$A,0)) -> PT Fastener Nusantara | F12: MAT-00004 | G12: =INDEX('01_Master_Material'!$B:$B,MATCH(F12,'01_Master_Material'!$A:$A,0)) -> Hex Bolt M12x50 Grade 8.8 | H12: =INDEX('01_Master_Material'!#REF!,MATCH(F12,'01_Master_Material'!$A:$A,0)) -> #REF! | I12: 50 | J12: 33.5 | K12: =I12*J12 -> 1675 | L12: =INDEX('01_Master_Material'!#REF!,MATCH(F12,'01_Master_Material'!$A:$A,0)) -> #REF! | M12: =INDEX('01_Master_Material'!$G:$G,MATCH(F12,'01_Master_Material'!$A:$A,0))*L12 -> #REF! | N12: =J12-M12 -> #REF! | O12: =IFERROR(N12/M12,0) -> 0 | P12: Standard | Q12: =INDEX('01_Master_Material'!$L:$L,MATCH(F12,'01_Master_Material'!$A:$A,0)) -> 10 | R12: =C12+Q12 -> 46198 | S12: No | T12: =IF($S12="Yes","Cancelled",IF(SUMIFS('05_Goods_Receipt'!$N:$N,'05_Goods_Receipt'!$D:$D,$A12,'05_Goods_Receipt'!$E:$E,$B12)>=I12,"Closed",IF(SUMIFS('05_Goods_Receipt'!$N:$N,'05_Goods_Receipt'!$D:$D,$A12,'05_Goods_Receipt'!$E:$E,$B12)>0,"Partially Received","Open"))) -> Closed | V12: =A12&"-"&B12 -> PO-2026-0005-10
A13: PO-2026-0005 | B13: 20 | C13: 46188 | D13: SUP-0009 | E13: =INDEX('02_Master_Supplier'!$B:$B,MATCH(D13,'02_Master_Supplier'!$A:$A,0)) -> PT Fastener Nusantara | F13: MAT-00014 | G13: =INDEX('01_Master_Material'!$B:$B,MATCH(F13,'01_Master_Material'!$A:$A,0)) -> Flat Washer M12 Zinc Plated | H13: =INDEX('01_Master_Material'!#REF!,MATCH(F13,'01_Master_Material'!$A:$A,0)) -> #REF! | I13: 40 | J13: 9.8 | K13: =I13*J13 -> 392 | L13: =INDEX('01_Master_Material'!#REF!,MATCH(F13,'01_Master_Material'!$A:$A,0)) -> #REF! | M13: =INDEX('01_Master_Material'!$G:$G,MATCH(F13,'01_Master_Material'!$A:$A,0))*L13 -> #REF! | N13: =J13-M13 -> #REF! | O13: =IFERROR(N13/M13,0) -> 0 | P13: Standard | Q13: =INDEX('01_Master_Material'!$L:$L,MATCH(F13,'01_Master_Material'!$A:$A,0)) -> 10 | R13: =C13+Q13 -> 46198 | S13: No | T13: =IF($S13="Yes","Cancelled",IF(SUMIFS('05_Goods_Receipt'!$N:$N,'05_Goods_Receipt'!$D:$D,$A13,'05_Goods_Receipt'!$E:$E,$B13)>=I13,"Closed",IF(SUMIFS('05_Goods_Receipt'!$N:$N,'05_Goods_Receipt'!$D:$D,$A13,'05_Goods_Receipt'!$E:$E,$B13)>0,"Partially Received","Open"))) -> Closed | V13: =A13&"-"&B13 -> PO-2026-0005-20
A16: Notes / Data Dictionary
A17: - PO Number + PO Line: Composite key, combined into 'PO Line Key' (column V) for simple single-column lookups from 05_Goods_Receipt.
A18: - Supplier Name, Material Description, Purchase UoM, Conversion Factor, Lead Time: pulled live via INDEX/MATCH from the master sheets (green font = cross-sheet link).
A19: - Standard Cost Equivalent = Material Standard Cost x Conversion Factor, converted into Purchase UoM terms to compare directly against the negotiated Unit Price.
A20: - Price Variance = Unit Price - Standard Cost Equivalent. Positive = paid above standard cost; Negative = paid below standard cost.
A21: - Expected Delivery Date = PO Date + Lead Time (Days) from Material Master.
A22: - Cancelled Flag: Manual override. PO cancellation is a business decision that cannot be inferred from receiving data, so it is kept as an explicit input.
A23: - PO Status: NOW FORMULA-DRIVEN (updated from Sheet 04 v1). Checks Cancelled Flag first; otherwise compares SUMIFS of Quantity Accepted in 05_Goods_Receipt against Order Quantity to derive Open / Partially Received / Closed.
A24: - Font color convention: blue = manual input, green = cross-sheet lookup formula, black = same-row calculated formula, grey italic = helper/technical column.

Sheet 05_Goods_Receipt
A1: 05_GOODS_RECEIPT | Warehouse Operations in a Heavy Equipment Manufacturing Environment
A3: GR Number | B3: GR Line | C3: GR Date | D3: PO Number | E3: PO Line | F3: PO Line Key (Helper) | G3: Supplier Name | H3: Material Code | I3: Material Description | J3: Order Quantity (Ref) | K3: Unit Price (Ref) | L3: UoM (Ref) | M3: Quantity Received | N3: Quantity Accepted | O3: Quantity Rejected | P3: Inspection Result | Q3: Rejection Reason | R3: Batch/Lot Number | S3: Receiving Location (Dock) | T3: Expected Delivery Date (Ref) | U3: Delivery Status | V3: Quantity Variance | W3: Quantity Variance % | X3: Put-Away Status | Y3: Remarks | Z3: GR Line Key (Helper)
A4: GR-2026-0001 | B4: 10 | C4: 46187 | D4: PO-2026-0001 | E4: 10 | F4: =D4&"-"&E4 -> PO-2026-0001-10 | G4: =INDEX('04_Purchase_Order'!$E:$E,MATCH(F4,'04_Purchase_Order'!$V:$V,0)) -> Komatsu Parts Indonesia | H4: =INDEX('04_Purchase_Order'!$F:$F,MATCH(F4,'04_Purchase_Order'!$V:$V,0)) -> MAT-00001 | I4: =INDEX('01_Master_Material'!$B:$B,MATCH(H4,'01_Master_Material'!$A:$A,0)) -> Hydraulic Cylinder Seal Kit 80mm | J4: =INDEX('04_Purchase_Order'!$I:$I,MATCH(F4,'04_Purchase_Order'!$V:$V,0)) -> 5 | K4: =INDEX('04_Purchase_Order'!$J:$J,MATCH(F4,'04_Purchase_Order'!$V:$V,0)) -> 1500 | L4: =INDEX('04_Purchase_Order'!$H:$H,MATCH(F4,'04_Purchase_Order'!$V:$V,0)) -> #REF! | M4: 5 | N4: 5 | O4: =M4-N4 -> 0 | P4: =IF(O4=0,"Fully Accepted",IF(N4=0,"Fully Rejected","Partially Accepted")) -> Fully Accepted | Q4: N/A | R4: HYD-SEAL-2606A | S4: RCV-DOCK-01 | T4: =INDEX('04_Purchase_Order'!$R:$R,MATCH(F4,'04_Purchase_Order'!$V:$V,0)) -> 46188 | U4: =IF(C4<=T4,"On-Time","Late") -> On-Time | V4: =M4-J4 -> 0 | W4: =IFERROR(V4/J4,0) -> 0 | X4: =IF(COUNTIF('06_Put_Away'!$F:$F,Z4)>0,"Completed","Pending") -> Completed | Z4: =A4&"-"&B4 -> GR-2026-0001-10
A5: GR-2026-0001 | B5: 20 | C5: 46187 | D5: PO-2026-0001 | E5: 20 | F5: =D5&"-"&E5 -> PO-2026-0001-20 | G5: =INDEX('04_Purchase_Order'!$E:$E,MATCH(F5,'04_Purchase_Order'!$V:$V,0)) -> Komatsu Parts Indonesia | H5: =INDEX('04_Purchase_Order'!$F:$F,MATCH(F5,'04_Purchase_Order'!$V:$V,0)) -> MAT-00008 | I5: =INDEX('01_Master_Material'!$B:$B,MATCH(H5,'01_Master_Material'!$A:$A,0)) -> Hydraulic Hose 1/2in x 3m | J5: =INDEX('04_Purchase_Order'!$I:$I,MATCH(F5,'04_Purchase_Order'!$V:$V,0)) -> 30 | K5: =INDEX('04_Purchase_Order'!$J:$J,MATCH(F5,'04_Purchase_Order'!$V:$V,0)) -> 52 | L5: =INDEX('04_Purchase_Order'!$H:$H,MATCH(F5,'04_Purchase_Order'!$V:$V,0)) -> #REF! | M5: 30 | N5: 28 | O5: =M5-N5 -> 2 | P5: =IF(O5=0,"Fully Accepted",IF(N5=0,"Fully Rejected","Partially Accepted")) -> Partially Accepted | Q5: Damaged in Transit | R5: HYD-HOSE-2606B | S5: RCV-DOCK-01 | T5: =INDEX('04_Purchase_Order'!$R:$R,MATCH(F5,'04_Purchase_Order'!$V:$V,0)) -> 46186 | U5: =IF(C5<=T5,"On-Time","Late") -> Late | V5: =M5-J5 -> 0 | W5: =IFERROR(V5/J5,0) -> 0 | X5: =IF(COUNTIF('06_Put_Away'!$F:$F,Z5)>0,"Completed","Pending") -> Completed | Y5: 2 units damaged, requested replacement | Z5: =A5&"-"&B5 -> GR-2026-0001-20
A6: GR-2026-0002 | B6: 10 | C6: 46184 | D6: PO-2026-0002 | E6: 20 | F6: =D6&"-"&E6 -> PO-2026-0002-20 | G6: =INDEX('04_Purchase_Order'!$E:$E,MATCH(F6,'04_Purchase_Order'!$V:$V,0)) -> Caterpillar Engine Parts Distributor | H6: =INDEX('04_Purchase_Order'!$F:$F,MATCH(F6,'04_Purchase_Order'!$V:$V,0)) -> MAT-00003 | I6: =INDEX('01_Master_Material'!$B:$B,MATCH(H6,'01_Master_Material'!$A:$A,0)) -> Engine Oil Filter (Cat 320D) | J6: =INDEX('04_Purchase_Order'!$I:$I,MATCH(F6,'04_Purchase_Order'!$V:$V,0)) -> 10 | K6: =INDEX('04_Purchase_Order'!$J:$J,MATCH(F6,'04_Purchase_Order'!$V:$V,0)) -> 430 | L6: =INDEX('04_Purchase_Order'!$H:$H,MATCH(F6,'04_Purchase_Order'!$V:$V,0)) -> #REF! | M6: 6 | N6: 6 | O6: =M6-N6 -> 0 | P6: =IF(O6=0,"Fully Accepted",IF(N6=0,"Fully Rejected","Partially Accepted")) -> Fully Accepted | Q6: N/A | R6: OILFLT-2606C | S6: RCV-DOCK-01 | T6: =INDEX('04_Purchase_Order'!$R:$R,MATCH(F6,'04_Purchase_Order'!$V:$V,0)) -> 46185 | U6: =IF(C6<=T6,"On-Time","Late") -> On-Time | V6: =M6-J6 -> -4 | W6: =IFERROR(V6/J6,0) -> -0.4 | X6: =IF(COUNTIF('06_Put_Away'!$F:$F,Z6)>0,"Completed","Pending") -> Completed | Y6: Partial shipment, remainder still pending from supplier | Z6: =A6&"-"&B6 -> GR-2026-0002-10
A7: GR-2026-0003 | B7: 10 | C7: 46197 | D7: PO-2026-0005 | E7: 10 | F7: =D7&"-"&E7 -> PO-2026-0005-10 | G7: =INDEX('04_Purchase_Order'!$E:$E,MATCH(F7,'04_Purchase_Order'!$V:$V,0)) -> PT Fastener Nusantara | H7: =INDEX('04_Purchase_Order'!$F:$F,MATCH(F7,'04_Purchase_Order'!$V:$V,0)) -> MAT-00004 | I7: =INDEX('01_Master_Material'!$B:$B,MATCH(H7,'01_Master_Material'!$A:$A,0)) -> Hex Bolt M12x50 Grade 8.8 | J7: =INDEX('04_Purchase_Order'!$I:$I,MATCH(F7,'04_Purchase_Order'!$V:$V,0)) -> 50 | K7: =INDEX('04_Purchase_Order'!$J:$J,MATCH(F7,'04_Purchase_Order'!$V:$V,0)) -> 33.5 | L7: =INDEX('04_Purchase_Order'!$H:$H,MATCH(F7,'04_Purchase_Order'!$V:$V,0)) -> #REF! | M7: 50 | N7: 50 | O7: =M7-N7 -> 0 | P7: =IF(O7=0,"Fully Accepted",IF(N7=0,"Fully Rejected","Partially Accepted")) -> Fully Accepted | Q7: N/A | S7: RCV-DOCK-01 | T7: =INDEX('04_Purchase_Order'!$R:$R,MATCH(F7,'04_Purchase_Order'!$V:$V,0)) -> 46198 | U7: =IF(C7<=T7,"On-Time","Late") -> On-Time | V7: =M7-J7 -> 0 | W7: =IFERROR(V7/J7,0) -> 0 | X7: =IF(COUNTIF('06_Put_Away'!$F:$F,Z7)>0,"Completed","Pending") -> Completed | Z7: =A7&"-"&B7 -> GR-2026-0003-10
A8: GR-2026-0004 | B8: 10 | C8: 46199 | D8: PO-2026-0005 | E8: 20 | F8: =D8&"-"&E8 -> PO-2026-0005-20 | G8: =INDEX('04_Purchase_Order'!$E:$E,MATCH(F8,'04_Purchase_Order'!$V:$V,0)) -> PT Fastener Nusantara | H8: =INDEX('04_Purchase_Order'!$F:$F,MATCH(F8,'04_Purchase_Order'!$V:$V,0)) -> MAT-00014 | I8: =INDEX('01_Master_Material'!$B:$B,MATCH(H8,'01_Master_Material'!$A:$A,0)) -> Flat Washer M12 Zinc Plated | J8: =INDEX('04_Purchase_Order'!$I:$I,MATCH(F8,'04_Purchase_Order'!$V:$V,0)) -> 40 | K8: =INDEX('04_Purchase_Order'!$J:$J,MATCH(F8,'04_Purchase_Order'!$V:$V,0)) -> 9.8 | L8: =INDEX('04_Purchase_Order'!$H:$H,MATCH(F8,'04_Purchase_Order'!$V:$V,0)) -> #REF! | M8: 40 | N8: 40 | O8: =M8-N8 -> 0 | P8: =IF(O8=0,"Fully Accepted",IF(N8=0,"Fully Rejected","Partially Accepted")) -> Fully Accepted | Q8: N/A | S8: RCV-DOCK-01 | T8: =INDEX('04_Purchase_Order'!$R:$R,MATCH(F8,'04_Purchase_Order'!$V:$V,0)) -> 46198 | U8: =IF(C8<=T8,"On-Time","Late") -> Late | V8: =M8-J8 -> 0 | W8: =IFERROR(V8/J8,0) -> 0 | X8: =IF(COUNTIF('06_Put_Away'!$F:$F,Z8)>0,"Completed","Pending") -> Completed | Y8: Slight delay from supplier | Z8: =A8&"-"&B8 -> GR-2026-0004-10
A11: Notes / Data Dictionary
A12: - GR Number + GR Line: Composite key. One GR Number can cover multiple lines received in the same physical delivery.
A13: - PO Line Key (Helper) = PO Number & PO Line, used for single-column INDEX/MATCH lookups back to 04_Purchase_Order (avoids fragile two-criteria array formulas).
A14: - Quantity Accepted vs Quantity Received: deliberately separate. A shipment can arrive complete (Received) but partially fail QC (Accepted < Received), which correctly keeps the related PO 'Partially Received' rather than falsely 'Closed'.
A15: - Delivery Status = On-Time if GR Date <= Expected Delivery Date (from PO), else Late. Feeds the Dashboard's supplier on-time delivery KPI.
A16: - Quantity Variance = Quantity Received - Order Quantity (Ref). Negative = under-shipment; positive = over-shipment.
A17: - Batch/Lot Number: Optional. Recommended for Critical Spare and hydraulic/engine components to support warranty/defect traceability.
A18: - Put-Away Status: FORMULA-DRIVEN (updated from Sheet 05 v1). Uses COUNTIF against 06_Put_Away's GR Line Key column to detect whether this receipt has already been shelved.

Sheet 06_Put_Away
A1: 06_PUT_AWAY | Warehouse Operations in a Heavy Equipment Manufacturing Environment
A3: Put-Away Number | B3: Put-Away Line | C3: Put-Away Date | D3: GR Number | E3: GR Line | F3: GR Line Key (Helper) | G3: Material Code | H3: Material Description | I3: Quantity Accepted (Ref, Purchase UoM) | J3: Purchase UoM (Ref) | K3: Conversion Factor (Ref) | L3: Quantity Put-Away (Base UoM) | M3: Base UoM (Ref) | N3: Storage/Handling Class (Ref) | O3: Putaway Location | P3: Location Storage/Handling Requirement (Ref) | Q3: Location Match Check | R3: Putaway Status | S3: GR Date (Ref) | T3: Putaway Lead Time (Days) | U3: Remarks | V3: Put-Away Line Key (Helper)
A4: PA-2026-0001 | B4: 10 | C4: 46188 | D4: GR-2026-0001 | E4: 10 | F4: =D4&"-"&E4 -> GR-2026-0001-10 | G4: =INDEX('05_Goods_Receipt'!$H:$H,MATCH(F4,'05_Goods_Receipt'!$Z:$Z,0)) -> MAT-00001 | H4: =INDEX('01_Master_Material'!$B:$B,MATCH(G4,'01_Master_Material'!$A:$A,0)) -> Hydraulic Cylinder Seal Kit 80mm | I4: =INDEX('05_Goods_Receipt'!$N:$N,MATCH(F4,'05_Goods_Receipt'!$Z:$Z,0)) -> 5 | J4: =INDEX('05_Goods_Receipt'!$L:$L,MATCH(F4,'05_Goods_Receipt'!$Z:$Z,0)) -> #REF! | K4: =INDEX('01_Master_Material'!#REF!,MATCH(G4,'01_Master_Material'!$A:$A,0)) -> #REF! | L4: =I4*K4 -> #REF! | M4: =INDEX('01_Master_Material'!$D:$D,MATCH(G4,'01_Master_Material'!$A:$A,0)) -> PCS | N4: =INDEX('01_Master_Material'!$I:$I,MATCH(G4,'01_Master_Material'!$A:$A,0)) -> Standard | O4: RCK-B-01-01 | P4: =INDEX('03_Master_Location'!$D:$D,MATCH(O4,'03_Master_Location'!$A:$A,0)) -> Standard | Q4: =IF(N4=P4,"Match","Mismatch - Review") -> Match | R4: =IF(Q4="Match","Completed","Exception - Needs Review") -> Completed | S4: =INDEX('05_Goods_Receipt'!$C:$C,MATCH(F4,'05_Goods_Receipt'!$Z:$Z,0)) -> 46187 | T4: =C4-S4 -> 1 | V4: =A4&"-"&B4 -> PA-2026-0001-10
A5: PA-2026-0001 | B5: 20 | C5: 46188 | D5: GR-2026-0001 | E5: 20 | F5: =D5&"-"&E5 -> GR-2026-0001-20 | G5: =INDEX('05_Goods_Receipt'!$H:$H,MATCH(F5,'05_Goods_Receipt'!$Z:$Z,0)) -> MAT-00008 | H5: =INDEX('01_Master_Material'!$B:$B,MATCH(G5,'01_Master_Material'!$A:$A,0)) -> Hydraulic Hose 1/2in x 3m | I5: =INDEX('05_Goods_Receipt'!$N:$N,MATCH(F5,'05_Goods_Receipt'!$Z:$Z,0)) -> 28 | J5: =INDEX('05_Goods_Receipt'!$L:$L,MATCH(F5,'05_Goods_Receipt'!$Z:$Z,0)) -> #REF! | K5: =INDEX('01_Master_Material'!#REF!,MATCH(G5,'01_Master_Material'!$A:$A,0)) -> #REF! | L5: =I5*K5 -> #REF! | M5: =INDEX('01_Master_Material'!$D:$D,MATCH(G5,'01_Master_Material'!$A:$A,0)) -> PCS | N5: =INDEX('01_Master_Material'!$I:$I,MATCH(G5,'01_Master_Material'!$A:$A,0)) -> Standard | O5: RCK-B-01-02 | P5: =INDEX('03_Master_Location'!$D:$D,MATCH(O5,'03_Master_Location'!$A:$A,0)) -> Standard | Q5: =IF(N5=P5,"Match","Mismatch - Review") -> Match | R5: =IF(Q5="Match","Completed","Exception - Needs Review") -> Completed | S5: =INDEX('05_Goods_Receipt'!$C:$C,MATCH(F5,'05_Goods_Receipt'!$Z:$Z,0)) -> 46187 | T5: =C5-S5 -> 1 | V5: =A5&"-"&B5 -> PA-2026-0001-20
A6: PA-2026-0002 | B6: 10 | C6: 46186 | D6: GR-2026-0002 | E6: 10 | F6: =D6&"-"&E6 -> GR-2026-0002-10 | G6: =INDEX('05_Goods_Receipt'!$H:$H,MATCH(F6,'05_Goods_Receipt'!$Z:$Z,0)) -> MAT-00003 | H6: =INDEX('01_Master_Material'!$B:$B,MATCH(G6,'01_Master_Material'!$A:$A,0)) -> Engine Oil Filter (Cat 320D) | I6: =INDEX('05_Goods_Receipt'!$N:$N,MATCH(F6,'05_Goods_Receipt'!$Z:$Z,0)) -> 6 | J6: =INDEX('05_Goods_Receipt'!$L:$L,MATCH(F6,'05_Goods_Receipt'!$Z:$Z,0)) -> #REF! | K6: =INDEX('01_Master_Material'!#REF!,MATCH(G6,'01_Master_Material'!$A:$A,0)) -> #REF! | L6: =I6*K6 -> #REF! | M6: =INDEX('01_Master_Material'!$D:$D,MATCH(G6,'01_Master_Material'!$A:$A,0)) -> PCS | N6: =INDEX('01_Master_Material'!$I:$I,MATCH(G6,'01_Master_Material'!$A:$A,0)) -> Standard | O6: RCK-B-02-01 | P6: =INDEX('03_Master_Location'!$D:$D,MATCH(O6,'03_Master_Location'!$A:$A,0)) -> Standard | Q6: =IF(N6=P6,"Match","Mismatch - Review") -> Match | R6: =IF(Q6="Match","Completed","Exception - Needs Review") -> Completed | S6: =INDEX('05_Goods_Receipt'!$C:$C,MATCH(F6,'05_Goods_Receipt'!$Z:$Z,0)) -> 46184 | T6: =C6-S6 -> 2 | V6: =A6&"-"&B6 -> PA-2026-0002-10
A7: PA-2026-0003 | B7: 10 | C7: 46199 | D7: GR-2026-0003 | E7: 10 | F7: =D7&"-"&E7 -> GR-2026-0003-10 | G7: =INDEX('05_Goods_Receipt'!$H:$H,MATCH(F7,'05_Goods_Receipt'!$Z:$Z,0)) -> MAT-00004 | H7: =INDEX('01_Master_Material'!$B:$B,MATCH(G7,'01_Master_Material'!$A:$A,0)) -> Hex Bolt M12x50 Grade 8.8 | I7: =INDEX('05_Goods_Receipt'!$N:$N,MATCH(F7,'05_Goods_Receipt'!$Z:$Z,0)) -> 50 | J7: =INDEX('05_Goods_Receipt'!$L:$L,MATCH(F7,'05_Goods_Receipt'!$Z:$Z,0)) -> #REF! | K7: =INDEX('01_Master_Material'!#REF!,MATCH(G7,'01_Master_Material'!$A:$A,0)) -> #REF! | L7: =I7*K7 -> #REF! | M7: =INDEX('01_Master_Material'!$D:$D,MATCH(G7,'01_Master_Material'!$A:$A,0)) -> PCS | N7: =INDEX('01_Master_Material'!$I:$I,MATCH(G7,'01_Master_Material'!$A:$A,0)) -> Standard | O7: HAZ-C-01 | P7: =INDEX('03_Master_Location'!$D:$D,MATCH(O7,'03_Master_Location'!$A:$A,0)) -> Hazardous | Q7: =IF(N7=P7,"Match","Mismatch - Review") -> Mismatch - Review | R7: =IF(Q7="Match","Completed","Exception - Needs Review") -> Exception - Needs Review | S7: =INDEX('05_Goods_Receipt'!$C:$C,MATCH(F7,'05_Goods_Receipt'!$Z:$Z,0)) -> 46197 | T7: =C7-S7 -> 2 | U7: Placed in wrong location by mistake - flagged for correction | V7: =A7&"-"&B7 -> PA-2026-0003-10
A8: PA-2026-0004 | B8: 10 | C8: 46202 | D8: GR-2026-0004 | E8: 10 | F8: =D8&"-"&E8 -> GR-2026-0004-10 | G8: =INDEX('05_Goods_Receipt'!$H:$H,MATCH(F8,'05_Goods_Receipt'!$Z:$Z,0)) -> MAT-00014 | H8: =INDEX('01_Master_Material'!$B:$B,MATCH(G8,'01_Master_Material'!$A:$A,0)) -> Flat Washer M12 Zinc Plated | I8: =INDEX('05_Goods_Receipt'!$N:$N,MATCH(F8,'05_Goods_Receipt'!$Z:$Z,0)) -> 40 | J8: =INDEX('05_Goods_Receipt'!$L:$L,MATCH(F8,'05_Goods_Receipt'!$Z:$Z,0)) -> #REF! | K8: =INDEX('01_Master_Material'!#REF!,MATCH(G8,'01_Master_Material'!$A:$A,0)) -> #REF! | L8: =I8*K8 -> #REF! | M8: =INDEX('01_Master_Material'!$D:$D,MATCH(G8,'01_Master_Material'!$A:$A,0)) -> PCS | N8: =INDEX('01_Master_Material'!$I:$I,MATCH(G8,'01_Master_Material'!$A:$A,0)) -> Standard | O8: RCK-B-02-01 | P8: =INDEX('03_Master_Location'!$D:$D,MATCH(O8,'03_Master_Location'!$A:$A,0)) -> Standard | Q8: =IF(N8=P8,"Match","Mismatch - Review") -> Match | R8: =IF(Q8="Match","Completed","Exception - Needs Review") -> Completed | S8: =INDEX('05_Goods_Receipt'!$C:$C,MATCH(F8,'05_Goods_Receipt'!$Z:$Z,0)) -> 46199 | T8: =C8-S8 -> 3 | V8: =A8&"-"&B8 -> PA-2026-0004-10
A11: Notes / Data Dictionary
A12: - GR Line Key (Helper) = GR Number & GR Line, used for single-column INDEX/MATCH lookups back to 05_Goods_Receipt.
A13: - Quantity Put-Away (Base UoM) = Quantity Accepted (Purchase UoM) x Conversion Factor. This is the actual stock quantity that will feed 10_Stock_Card.
A14: - Architecture decision: Stock Card draws its 'stock in' transaction from Put-Away, not directly from Goods Receipt, because Stock Card requires a Location dimension that only exists after this step.
A15: - Location Match Check compares the material's required Storage/Handling Class against the chosen location's actual requirement, flagging any mismatch for review - this simulates a real putaway-verification control.
A16: - Putaway Lead Time (Days) = Put-Away Date - GR Date (Ref). Feeds a Dashboard KPI on receiving-to-shelf efficiency.
A17: - Sample data intentionally includes one mismatch (PA-2026-0003) to demonstrate the validation catching a real placement error.

Sheet 07_Material_Request
A1: 07_MATERIAL_REQUEST | Warehouse Operations in a Heavy Equipment Manufacturing Environment
A3: Request Number | B3: Request Line | C3: Request Date | D3: Requesting Department | E3: Material Code | F3: Material Description | G3: Base UoM (Ref) | H3: Quantity Requested | I3: Request Priority | J3: Required Date | K3: Total Put-Away (Ref) | L3: Total Issued (Ref) | M3: Available Stock (Calculated) | N3: Stock Sufficiency Check | O3: Request Status | P3: Remarks | Q3: Request Line Key (Helper)
A4: MR-2026-0001 | B4: 10 | C4: 46189 | D4: Production | E4: MAT-00001 | F4: =INDEX('01_Master_Material'!$B:$B,MATCH(E4,'01_Master_Material'!$A:$A,0)) -> Hydraulic Cylinder Seal Kit 80mm | G4: =INDEX('01_Master_Material'!$D:$D,MATCH(E4,'01_Master_Material'!$A:$A,0)) -> PCS | H4: 4 | I4: Routine | J4: 46191 | K4: =SUMIF('06_Put_Away'!$G:$G,E4,'06_Put_Away'!$L:$L) -> #REF! | L4: =SUMIF('09_Goods_Issue'!$G:$G,E4,'09_Goods_Issue'!$M:$M) -> 4 | M4: =K4-L4 -> #REF! | N4: =IF(M4>=H4,"Sufficient","Insufficient - Review") -> #REF! | O4: Open | Q4: =A4&"-"&B4 -> MR-2026-0001-10
A5: MR-2026-0001 | B5: 20 | C5: 46189 | D5: Production | E5: MAT-00008 | F5: =INDEX('01_Master_Material'!$B:$B,MATCH(E5,'01_Master_Material'!$A:$A,0)) -> Hydraulic Hose 1/2in x 3m | G5: =INDEX('01_Master_Material'!$D:$D,MATCH(E5,'01_Master_Material'!$A:$A,0)) -> PCS | H5: 20 | I5: Routine | J5: 46191 | K5: =SUMIF('06_Put_Away'!$G:$G,E5,'06_Put_Away'!$L:$L) -> #REF! | L5: =SUMIF('09_Goods_Issue'!$G:$G,E5,'09_Goods_Issue'!$M:$M) -> 19 | M5: =K5-L5 -> #REF! | N5: =IF(M5>=H5,"Sufficient","Insufficient - Review") -> #REF! | O5: Open | Q5: =A5&"-"&B5 -> MR-2026-0001-20
A6: MR-2026-0002 | B6: 10 | C6: 46187 | D6: Maintenance | E6: MAT-00003 | F6: =INDEX('01_Master_Material'!$B:$B,MATCH(E6,'01_Master_Material'!$A:$A,0)) -> Engine Oil Filter (Cat 320D) | G6: =INDEX('01_Master_Material'!$D:$D,MATCH(E6,'01_Master_Material'!$A:$A,0)) -> PCS | H6: 100 | I6: Urgent | J6: 46188 | K6: =SUMIF('06_Put_Away'!$G:$G,E6,'06_Put_Away'!$L:$L) -> #REF! | L6: =SUMIF('09_Goods_Issue'!$G:$G,E6,'09_Goods_Issue'!$M:$M) -> 100 | M6: =K6-L6 -> #REF! | N6: =IF(M6>=H6,"Sufficient","Insufficient - Review") -> #REF! | O6: Open | P6: Machine down - urgent filter replacement | Q6: =A6&"-"&B6 -> MR-2026-0002-10
A7: MR-2026-0003 | B7: 10 | C7: 46200 | D7: Production | E7: MAT-00004 | F7: =INDEX('01_Master_Material'!$B:$B,MATCH(E7,'01_Master_Material'!$A:$A,0)) -> Hex Bolt M12x50 Grade 8.8 | G7: =INDEX('01_Master_Material'!$D:$D,MATCH(E7,'01_Master_Material'!$A:$A,0)) -> PCS | H7: 3000 | I7: Routine | J7: 46203 | K7: =SUMIF('06_Put_Away'!$G:$G,E7,'06_Put_Away'!$L:$L) -> #REF! | L7: =SUMIF('09_Goods_Issue'!$G:$G,E7,'09_Goods_Issue'!$M:$M) -> 3000 | M7: =K7-L7 -> #REF! | N7: =IF(M7>=H7,"Sufficient","Insufficient - Review") -> #REF! | O7: Open | Q7: =A7&"-"&B7 -> MR-2026-0003-10
A8: MR-2026-0004 | B8: 10 | C8: 46203 | D8: Production | E8: MAT-00014 | F8: =INDEX('01_Master_Material'!$B:$B,MATCH(E8,'01_Master_Material'!$A:$A,0)) -> Flat Washer M12 Zinc Plated | G8: =INDEX('01_Master_Material'!$D:$D,MATCH(E8,'01_Master_Material'!$A:$A,0)) -> PCS | H8: 9000 | I8: Routine | J8: 46205 | K8: =SUMIF('06_Put_Away'!$G:$G,E8,'06_Put_Away'!$L:$L) -> #REF! | L8: =SUMIF('09_Goods_Issue'!$G:$G,E8,'09_Goods_Issue'!$M:$M) -> 8000 | M8: =K8-L8 -> #REF! | N8: =IF(M8>=H8,"Sufficient","Insufficient - Review") -> #REF! | O8: Open | P8: Quantity exceeds available stock - to review | Q8: =A8&"-"&B8 -> MR-2026-0004-10
A11: Notes / Data Dictionary
A12: - Requesting Department: kept as a simple category (Production/Maintenance/QC), not a full cost-center code - no Finance/AP worksheet exists in this project to consume that level of detail.
A13: - Total Put-Away (Ref) = SUMIF of Quantity Put-Away (Base UoM) in 06_Put_Away for this material - i.e. everything ever shelved.
A14: - Total Issued (Ref) = SUMIF of Quantity Issued in 09_Goods_Issue for this material. Updated automatically as new issues are recorded.
A15: - Available Stock (Calculated) = Total Put-Away - Total Issued. This is designed to automatically become accurate once Goods Issue exists, without needing to redesign this sheet.
A16: - Stock Sufficiency Check flags whether available stock can cover this request - feeds 08_Picking_List and a Dashboard 'unfulfillable request' KPI.
A17: - Request Priority: mirrors the Order Priority concept in 04_Purchase_Order, giving a consistent 'urgent vs routine' language across the whole workbook.
A18: - IMPORTANT DESIGN NOTE: Available Stock (Calculated) reflects CURRENT total stock (Put-Away minus Issued to date), not the stock balance at the moment this request was made. Once older requests have been fully issued, this column will correctly show low/zero remaining stock even though the request itself was fulfilled successfully at the time. This is a known limitation of a flat transactional sheet without a point-in-time ledger - which is exactly why 10_Stock_Card exists: it provides a running balance per date/transaction rather than a single current-total snapshot.

Sheet 08_Picking_List
A1: 08_PICKING_LIST | Warehouse Operations in a Heavy Equipment Manufacturing Environment
A3: Pick Number | B3: Pick Line | C3: Pick Date | D3: Request Number | E3: Request Line | F3: Request Line Key (Helper) | G3: Material Code | H3: Material Description | I3: Requesting Department (Ref) | J3: Request Priority (Ref) | K3: Quantity Requested (Ref) | L3: Pick Location (Ref) | M3: Pick Location Pickable Check (Ref) | N3: Available Stock (Calculated) | O3: Quantity Allocated (Calculated) | P3: Quantity Picked | Q3: Pick Status | R3: Short-Pick Reason | S3: Remarks | T3: Pick Line Key (Helper)
A4: PL-2026-0001 | B4: 10 | C4: 46190 | D4: MR-2026-0001 | E4: 10 | F4: =D4&"-"&E4 -> MR-2026-0001-10 | G4: =INDEX('07_Material_Request'!$E:$E,MATCH(F4,'07_Material_Request'!$Q:$Q,0)) -> MAT-00001 | H4: =INDEX('01_Master_Material'!$B:$B,MATCH(G4,'01_Master_Material'!$A:$A,0)) -> Hydraulic Cylinder Seal Kit 80mm | I4: =INDEX('07_Material_Request'!$D:$D,MATCH(F4,'07_Material_Request'!$Q:$Q,0)) -> Production | J4: =INDEX('07_Material_Request'!$I:$I,MATCH(F4,'07_Material_Request'!$Q:$Q,0)) -> Routine | K4: =INDEX('07_Material_Request'!$H:$H,MATCH(F4,'07_Material_Request'!$Q:$Q,0)) -> 4 | L4: =INDEX('06_Put_Away'!$O:$O,MATCH(G4,'06_Put_Away'!$G:$G,0)) -> RCK-B-01-01 | M4: =INDEX('03_Master_Location'!$E:$E,MATCH(L4,'03_Master_Location'!$A:$A,0)) -> Yes | N4: =SUMIF('06_Put_Away'!$G:$G,G4,'06_Put_Away'!$L:$L)-SUMIF('09_Goods_Issue'!$G:$G,G4,'09_Goods_Issue'!$M:$M) -> #REF! | O4: =MIN(K4,N4) -> #REF! | P4: 4 | Q4: =IF(P4=0,"Not Picked",IF(P4<K4,"Partially Picked","Fully Picked")) -> Fully Picked | R4: N/A | T4: =A4&"-"&B4 -> PL-2026-0001-10
A5: PL-2026-0001 | B5: 20 | C5: 46190 | D5: MR-2026-0001 | E5: 20 | F5: =D5&"-"&E5 -> MR-2026-0001-20 | G5: =INDEX('07_Material_Request'!$E:$E,MATCH(F5,'07_Material_Request'!$Q:$Q,0)) -> MAT-00008 | H5: =INDEX('01_Master_Material'!$B:$B,MATCH(G5,'01_Master_Material'!$A:$A,0)) -> Hydraulic Hose 1/2in x 3m | I5: =INDEX('07_Material_Request'!$D:$D,MATCH(F5,'07_Material_Request'!$Q:$Q,0)) -> Production | J5: =INDEX('07_Material_Request'!$I:$I,MATCH(F5,'07_Material_Request'!$Q:$Q,0)) -> Routine | K5: =INDEX('07_Material_Request'!$H:$H,MATCH(F5,'07_Material_Request'!$Q:$Q,0)) -> 20 | L5: =INDEX('06_Put_Away'!$O:$O,MATCH(G5,'06_Put_Away'!$G:$G,0)) -> RCK-B-01-02 | M5: =INDEX('03_Master_Location'!$E:$E,MATCH(L5,'03_Master_Location'!$A:$A,0)) -> Yes | N5: =SUMIF('06_Put_Away'!$G:$G,G5,'06_Put_Away'!$L:$L)-SUMIF('09_Goods_Issue'!$G:$G,G5,'09_Goods_Issue'!$M:$M) -> #REF! | O5: =MIN(K5,N5) -> #REF! | P5: 20 | Q5: =IF(P5=0,"Not Picked",IF(P5<K5,"Partially Picked","Fully Picked")) -> Fully Picked | R5: N/A | T5: =A5&"-"&B5 -> PL-2026-0001-20
A6: PL-2026-0002 | B6: 10 | C6: 46187 | D6: MR-2026-0002 | E6: 10 | F6: =D6&"-"&E6 -> MR-2026-0002-10 | G6: =INDEX('07_Material_Request'!$E:$E,MATCH(F6,'07_Material_Request'!$Q:$Q,0)) -> MAT-00003 | H6: =INDEX('01_Master_Material'!$B:$B,MATCH(G6,'01_Master_Material'!$A:$A,0)) -> Engine Oil Filter (Cat 320D) | I6: =INDEX('07_Material_Request'!$D:$D,MATCH(F6,'07_Material_Request'!$Q:$Q,0)) -> Maintenance | J6: =INDEX('07_Material_Request'!$I:$I,MATCH(F6,'07_Material_Request'!$Q:$Q,0)) -> Urgent | K6: =INDEX('07_Material_Request'!$H:$H,MATCH(F6,'07_Material_Request'!$Q:$Q,0)) -> 100 | L6: =INDEX('06_Put_Away'!$O:$O,MATCH(G6,'06_Put_Away'!$G:$G,0)) -> RCK-B-02-01 | M6: =INDEX('03_Master_Location'!$E:$E,MATCH(L6,'03_Master_Location'!$A:$A,0)) -> Yes | N6: =SUMIF('06_Put_Away'!$G:$G,G6,'06_Put_Away'!$L:$L)-SUMIF('09_Goods_Issue'!$G:$G,G6,'09_Goods_Issue'!$M:$M) -> #REF! | O6: =MIN(K6,N6) -> #REF! | P6: 100 | Q6: =IF(P6=0,"Not Picked",IF(P6<K6,"Partially Picked","Fully Picked")) -> Fully Picked | R6: N/A | S6: Urgent request - same-day pick | T6: =A6&"-"&B6 -> PL-2026-0002-10
A7: PL-2026-0003 | B7: 10 | C7: 46201 | D7: MR-2026-0003 | E7: 10 | F7: =D7&"-"&E7 -> MR-2026-0003-10 | G7: =INDEX('07_Material_Request'!$E:$E,MATCH(F7,'07_Material_Request'!$Q:$Q,0)) -> MAT-00004 | H7: =INDEX('01_Master_Material'!$B:$B,MATCH(G7,'01_Master_Material'!$A:$A,0)) -> Hex Bolt M12x50 Grade 8.8 | I7: =INDEX('07_Material_Request'!$D:$D,MATCH(F7,'07_Material_Request'!$Q:$Q,0)) -> Production | J7: =INDEX('07_Material_Request'!$I:$I,MATCH(F7,'07_Material_Request'!$Q:$Q,0)) -> Routine | K7: =INDEX('07_Material_Request'!$H:$H,MATCH(F7,'07_Material_Request'!$Q:$Q,0)) -> 3000 | L7: =INDEX('06_Put_Away'!$O:$O,MATCH(G7,'06_Put_Away'!$G:$G,0)) -> HAZ-C-01 | M7: =INDEX('03_Master_Location'!$E:$E,MATCH(L7,'03_Master_Location'!$A:$A,0)) -> Yes | N7: =SUMIF('06_Put_Away'!$G:$G,G7,'06_Put_Away'!$L:$L)-SUMIF('09_Goods_Issue'!$G:$G,G7,'09_Goods_Issue'!$M:$M) -> #REF! | O7: =MIN(K7,N7) -> #REF! | P7: 3000 | Q7: =IF(P7=0,"Not Picked",IF(P7<K7,"Partially Picked","Fully Picked")) -> Fully Picked | R7: N/A | S7: Picked from HAZ-C-01 - flagged: verify this is the correct location for this material | T7: =A7&"-"&B7 -> PL-2026-0003-10
A8: PL-2026-0004 | B8: 10 | C8: 46204 | D8: MR-2026-0004 | E8: 10 | F8: =D8&"-"&E8 -> MR-2026-0004-10 | G8: =INDEX('07_Material_Request'!$E:$E,MATCH(F8,'07_Material_Request'!$Q:$Q,0)) -> MAT-00014 | H8: =INDEX('01_Master_Material'!$B:$B,MATCH(G8,'01_Master_Material'!$A:$A,0)) -> Flat Washer M12 Zinc Plated | I8: =INDEX('07_Material_Request'!$D:$D,MATCH(F8,'07_Material_Request'!$Q:$Q,0)) -> Production | J8: =INDEX('07_Material_Request'!$I:$I,MATCH(F8,'07_Material_Request'!$Q:$Q,0)) -> Routine | K8: =INDEX('07_Material_Request'!$H:$H,MATCH(F8,'07_Material_Request'!$Q:$Q,0)) -> 9000 | L8: =INDEX('06_Put_Away'!$O:$O,MATCH(G8,'06_Put_Away'!$G:$G,0)) -> RCK-B-02-01 | M8: =INDEX('03_Master_Location'!$E:$E,MATCH(L8,'03_Master_Location'!$A:$A,0)) -> Yes | N8: =SUMIF('06_Put_Away'!$G:$G,G8,'06_Put_Away'!$L:$L)-SUMIF('09_Goods_Issue'!$G:$G,G8,'09_Goods_Issue'!$M:$M) -> #REF! | O8: =MIN(K8,N8) -> #REF! | P8: 8000 | Q8: =IF(P8=0,"Not Picked",IF(P8<K8,"Partially Picked","Fully Picked")) -> Partially Picked | R8: Stock Shortage | S8: Only 8,000 available against 9,000 requested; remainder pending replenishment | T8: =A8&"-"&B8 -> PL-2026-0004-10
A11: Notes / Data Dictionary
A12: - Request Line Key (Helper) = Request Number & Request Line, mirroring the same helper-key pattern used in 04/05/06 to allow single-column INDEX/MATCH lookups.
A13: - Pick Location (Ref) is looked up automatically from 06_Put_Away by Material Code - it is NOT re-entered manually, so any placement error made during Put-Away flows through here automatically (see PL-2026-0003, which inherited the HAZ-C-01 mismatch from PA-2026-0003).
A14: - Pick Location Pickable Check (Ref) cross-checks the suggested location against 03_Master_Location's Pickable Flag, as a safety net in case a non-storage location is ever returned.
A15: - Available Stock (Calculated) = SUMIF of Quantity Put-Away for this material, minus SUMIF of Quantity Issued in 09_Goods_Issue. Fully live now that Goods Issue exists.
A16: - Quantity Allocated = MIN(Quantity Requested, Available Stock) - the system will never promise more than what is physically on the shelf.
A17: - Pick Status is derived automatically from Quantity Picked vs Quantity Requested, not manually set - this keeps the field trustworthy for the Dashboard's pick-fulfillment KPI.
A18: - IMPORTANT DESIGN NOTE: like 07_Material_Request, Available Stock (Calculated) here reflects the CURRENT running total, not the balance at the historical moment of this pick. Older picks may show low remaining stock now that their material has since been fully issued - this is expected, and is resolved properly in 10_Stock_Card's date-based running ledger.

Sheet 09_Goods_Issue
A1: 09_GOODS_ISSUE | Warehouse Operations in a Heavy Equipment Manufacturing Environment
A3: GI Number | B3: GI Line | C3: GI Date | D3: Pick Number | E3: Pick Line | F3: Pick Line Key (Helper) | G3: Material Code | H3: Material Description | I3: Base UoM (Ref) | J3: Issuing Location (Ref) | K3: Requesting Department (Ref) | L3: Quantity Picked (Ref) | M3: Quantity Issued | N3: Issue Variance | O3: Issue Variance Reason | P3: Remarks | Q3: GI Line Key (Helper)
A4: GI-2026-0001 | B4: 10 | C4: 46190 | D4: PL-2026-0001 | E4: 10 | F4: =D4&"-"&E4 -> PL-2026-0001-10 | G4: =INDEX('08_Picking_List'!$G:$G,MATCH(F4,'08_Picking_List'!$T:$T,0)) -> MAT-00001 | H4: =INDEX('01_Master_Material'!$B:$B,MATCH(G4,'01_Master_Material'!$A:$A,0)) -> Hydraulic Cylinder Seal Kit 80mm | I4: =INDEX('01_Master_Material'!$D:$D,MATCH(G4,'01_Master_Material'!$A:$A,0)) -> PCS | J4: =INDEX('08_Picking_List'!$L:$L,MATCH(F4,'08_Picking_List'!$T:$T,0)) -> RCK-B-01-01 | K4: =INDEX('08_Picking_List'!$I:$I,MATCH(F4,'08_Picking_List'!$T:$T,0)) -> Production | L4: =INDEX('08_Picking_List'!$P:$P,MATCH(F4,'08_Picking_List'!$T:$T,0)) -> 4 | M4: 4 | N4: =L4-M4 -> 0 | O4: N/A | Q4: =A4&"-"&B4 -> GI-2026-0001-10
A5: GI-2026-0001 | B5: 20 | C5: 46190 | D5: PL-2026-0001 | E5: 20 | F5: =D5&"-"&E5 -> PL-2026-0001-20 | G5: =INDEX('08_Picking_List'!$G:$G,MATCH(F5,'08_Picking_List'!$T:$T,0)) -> MAT-00008 | H5: =INDEX('01_Master_Material'!$B:$B,MATCH(G5,'01_Master_Material'!$A:$A,0)) -> Hydraulic Hose 1/2in x 3m | I5: =INDEX('01_Master_Material'!$D:$D,MATCH(G5,'01_Master_Material'!$A:$A,0)) -> PCS | J5: =INDEX('08_Picking_List'!$L:$L,MATCH(F5,'08_Picking_List'!$T:$T,0)) -> RCK-B-01-02 | K5: =INDEX('08_Picking_List'!$I:$I,MATCH(F5,'08_Picking_List'!$T:$T,0)) -> Production | L5: =INDEX('08_Picking_List'!$P:$P,MATCH(F5,'08_Picking_List'!$T:$T,0)) -> 20 | M5: 19 | N5: =L5-M5 -> 1 | O5: Damaged During Staging | P5: 1 unit found damaged during final check before handoff | Q5: =A5&"-"&B5 -> GI-2026-0001-20
A6: GI-2026-0002 | B6: 10 | C6: 46187 | D6: PL-2026-0002 | E6: 10 | F6: =D6&"-"&E6 -> PL-2026-0002-10 | G6: =INDEX('08_Picking_List'!$G:$G,MATCH(F6,'08_Picking_List'!$T:$T,0)) -> MAT-00003 | H6: =INDEX('01_Master_Material'!$B:$B,MATCH(G6,'01_Master_Material'!$A:$A,0)) -> Engine Oil Filter (Cat 320D) | I6: =INDEX('01_Master_Material'!$D:$D,MATCH(G6,'01_Master_Material'!$A:$A,0)) -> PCS | J6: =INDEX('08_Picking_List'!$L:$L,MATCH(F6,'08_Picking_List'!$T:$T,0)) -> RCK-B-02-01 | K6: =INDEX('08_Picking_List'!$I:$I,MATCH(F6,'08_Picking_List'!$T:$T,0)) -> Maintenance | L6: =INDEX('08_Picking_List'!$P:$P,MATCH(F6,'08_Picking_List'!$T:$T,0)) -> 100 | M6: 100 | N6: =L6-M6 -> 0 | O6: N/A | P6: Urgent request - same-day issue | Q6: =A6&"-"&B6 -> GI-2026-0002-10
A7: GI-2026-0003 | B7: 10 | C7: 46201 | D7: PL-2026-0003 | E7: 10 | F7: =D7&"-"&E7 -> PL-2026-0003-10 | G7: =INDEX('08_Picking_List'!$G:$G,MATCH(F7,'08_Picking_List'!$T:$T,0)) -> MAT-00004 | H7: =INDEX('01_Master_Material'!$B:$B,MATCH(G7,'01_Master_Material'!$A:$A,0)) -> Hex Bolt M12x50 Grade 8.8 | I7: =INDEX('01_Master_Material'!$D:$D,MATCH(G7,'01_Master_Material'!$A:$A,0)) -> PCS | J7: =INDEX('08_Picking_List'!$L:$L,MATCH(F7,'08_Picking_List'!$T:$T,0)) -> HAZ-C-01 | K7: =INDEX('08_Picking_List'!$I:$I,MATCH(F7,'08_Picking_List'!$T:$T,0)) -> Production | L7: =INDEX('08_Picking_List'!$P:$P,MATCH(F7,'08_Picking_List'!$T:$T,0)) -> 3000 | M7: 3000 | N7: =L7-M7 -> 0 | O7: N/A | P7: Issued from HAZ-C-01 - location discrepancy noted, recommend relocation at next cycle count | Q7: =A7&"-"&B7 -> GI-2026-0003-10
A8: GI-2026-0004 | B8: 10 | C8: 46204 | D8: PL-2026-0004 | E8: 10 | F8: =D8&"-"&E8 -> PL-2026-0004-10 | G8: =INDEX('08_Picking_List'!$G:$G,MATCH(F8,'08_Picking_List'!$T:$T,0)) -> MAT-00014 | H8: =INDEX('01_Master_Material'!$B:$B,MATCH(G8,'01_Master_Material'!$A:$A,0)) -> Flat Washer M12 Zinc Plated | I8: =INDEX('01_Master_Material'!$D:$D,MATCH(G8,'01_Master_Material'!$A:$A,0)) -> PCS | J8: =INDEX('08_Picking_List'!$L:$L,MATCH(F8,'08_Picking_List'!$T:$T,0)) -> RCK-B-02-01 | K8: =INDEX('08_Picking_List'!$I:$I,MATCH(F8,'08_Picking_List'!$T:$T,0)) -> Production | L8: =INDEX('08_Picking_List'!$P:$P,MATCH(F8,'08_Picking_List'!$T:$T,0)) -> 8000 | M8: 8000 | N8: =L8-M8 -> 0 | O8: N/A | P8: Partial fulfillment - 1,000 units still pending against MR-2026-0004 | Q8: =A8&"-"&B8 -> GI-2026-0004-10
A11: Notes / Data Dictionary
A12: - Pick Line Key (Helper) = Pick Number & Pick Line, mirroring the helper-key pattern used across 04-08 for single-column INDEX/MATCH lookups.
A13: - Quantity Picked (Ref) vs Quantity Issued: deliberately kept separate. Quantity Picked reflects what warehouse staff physically gathered; Quantity Issued reflects what was formally confirmed and handed over - these can differ if a final check before handoff finds a problem (see GI-2026-0001 line 20).
A14: - Issue Variance = Quantity Picked (Ref) - Quantity Issued. Positive means less was formally issued than was picked.
A15: - This sheet is the authoritative stock-out transaction: 10_Stock_Card will draw its 'stock out' side from here, and 07_Material_Request / 08_Picking_List's Available Stock calculations now subtract SUMIF totals from this sheet - both loops are now fully live, not placeholders.
A16: - Base UoM (Ref): Quantities here are in Base UoM, consistent with Put-Away, since conversion from Purchase UoM already happened upstream.

Sheet 10_Stock_Card
A1: 10_STOCK_CARD | Warehouse Operations in a Heavy Equipment Manufacturing Environment
A3: Stock Card Line | B3: Transaction Date | C3: Transaction Type | D3: Reference Number | E3: Reference Line | F3: Reference Key (Helper) | G3: Material Code | H3: Material Description | I3: Base UoM (Ref) | J3: Location (Ref) | K3: Quantity In | L3: Quantity Out | M3: Net Movement | N3: Running Balance (Qty) | O3: Unit Cost (Ref) | P3: Running Balance Value | Q3: Remarks
A4: 1 | B4: 46186 | C4: Receipt | D4: PA-2026-0002 | E4: 10 | F4: =D4&"-"&E4 -> PA-2026-0002-10 | G4: =IF(C4="Receipt",INDEX('06_Put_Away'!$G:$G,MATCH(F4,'06_Put_Away'!$V:$V,0)),INDEX('09_Goods_Issue'!$G:$G,MATCH(F4,'09_Goods_Issue'!$Q:$Q,0))) -> MAT-00003 | H4: =INDEX('01_Master_Material'!$B:$B,MATCH(G4,'01_Master_Material'!$A:$A,0)) -> Engine Oil Filter (Cat 320D) | I4: =INDEX('01_Master_Material'!$D:$D,MATCH(G4,'01_Master_Material'!$A:$A,0)) -> PCS | J4: =IF(C4="Receipt",INDEX('06_Put_Away'!$O:$O,MATCH(F4,'06_Put_Away'!$V:$V,0)),INDEX('09_Goods_Issue'!$J:$J,MATCH(F4,'09_Goods_Issue'!$Q:$Q,0))) -> RCK-B-02-01 | K4: =IF(C4="Receipt",INDEX('06_Put_Away'!$L:$L,MATCH(F4,'06_Put_Away'!$V:$V,0)),0) -> #REF! | L4: =IF(C4="Issue",INDEX('09_Goods_Issue'!$M:$M,MATCH(F4,'09_Goods_Issue'!$Q:$Q,0)),0) -> 0 | M4: =K4-L4 -> #REF! | N4: =SUMIFS($M$4:M4,$G$4:G4,G4) -> #REF! | O4: =INDEX('01_Master_Material'!$G:$G,MATCH(G4,'01_Master_Material'!$A:$A,0)) -> 250000 | P4: =N4*O4 -> #REF!
A5: 2 | B5: 46187 | C5: Issue | D5: GI-2026-0002 | E5: 10 | F5: =D5&"-"&E5 -> GI-2026-0002-10 | G5: =IF(C5="Receipt",INDEX('06_Put_Away'!$G:$G,MATCH(F5,'06_Put_Away'!$V:$V,0)),INDEX('09_Goods_Issue'!$G:$G,MATCH(F5,'09_Goods_Issue'!$Q:$Q,0))) -> MAT-00003 | H5: =INDEX('01_Master_Material'!$B:$B,MATCH(G5,'01_Master_Material'!$A:$A,0)) -> Engine Oil Filter (Cat 320D) | I5: =INDEX('01_Master_Material'!$D:$D,MATCH(G5,'01_Master_Material'!$A:$A,0)) -> PCS | J5: =IF(C5="Receipt",INDEX('06_Put_Away'!$O:$O,MATCH(F5,'06_Put_Away'!$V:$V,0)),INDEX('09_Goods_Issue'!$J:$J,MATCH(F5,'09_Goods_Issue'!$Q:$Q,0))) -> RCK-B-02-01 | K5: =IF(C5="Receipt",INDEX('06_Put_Away'!$L:$L,MATCH(F5,'06_Put_Away'!$V:$V,0)),0) -> 0 | L5: =IF(C5="Issue",INDEX('09_Goods_Issue'!$M:$M,MATCH(F5,'09_Goods_Issue'!$Q:$Q,0)),0) -> 100 | M5: =K5-L5 -> -100 | N5: =SUMIFS($M$4:M5,$G$4:G5,G5) -> #REF! | O5: =INDEX('01_Master_Material'!$G:$G,MATCH(G5,'01_Master_Material'!$A:$A,0)) -> 250000 | P5: =N5*O5 -> #REF!
